-----------------------------------------------------------------
2020-04-16 22:56:12.610281
Connection to Websocket lost. Restarting...
-----------------------------------------------------------------

-----------------------------------------------------------------
2020-04-16 22:56:12.611027
Uncaught exception
Traceback (most recent call last):
  File "/home/ubuntu/bitmex-kollector/util/kollector.py", line 42, in run_loop
    while(self.ws.ws.sock.connected):
AttributeError: 'NoneType' object has no attribute 'connected'

During handling of the above exception, another exception occurred:

Traceback (most recent call last):
  File "/home/ubuntu/bitmex-kollector/util/tools.py", line 35, in create_dirs
    os.mkdir(settings.DATA_DIR.replace('/', ''))
FileExistsError: [Errno 17] File exists: 'kollection'

During handling of the above exception, another exception occurred:

Traceback (most recent call last):
  File "main.py", line 6, in <module>
    kollector.run_loop()
  File "/home/ubuntu/bitmex-kollector/util/kollector.py", line 69, in run_loop
    self.reset()
  File "/home/ubuntu/bitmex-kollector/util/kollector.py", line 92, in reset
    self.run_loop()
  File "/home/ubuntu/bitmex-kollector/util/kollector.py", line 27, in run_loop
    tools.create_dirs()
  File "/home/ubuntu/bitmex-kollector/util/tools.py", line 59, in create_dirs
    print("Directories already exist.")
OSError: [Errno 5] Input/output error
-----------------------------------------------------------------

-----------------------------------------------------------------
2020-04-16 23:59:56.881945
Restarting...
-----------------------------------------------------------------

