-----------------------------------------------------------------
2020-05-16 21:26:55.559901
Uncaught exception
Traceback (most recent call last):
  File "main.py", line 16, in <module>
    kollector.run_loop()
  File "/var/www/html/bitmex-kollector/bitmex_kollector/kollector.py", line 89, in run_loop
    if not(self.check_connection()) and not(first_run):
  File "/var/www/html/bitmex-kollector/bitmex_kollector/kollector.py", line 283, in check_connection
    elapsed = now - dt.datetime.strptime(status['timestamp'], '%Y-%m-%d %H:%M:%S.%f')
  File "/usr/lib/python3.6/_strptime.py", line 565, in _strptime_datetime
    tt, fraction = _strptime(data_string, format)
  File "/usr/lib/python3.6/_strptime.py", line 362, in _strptime
    (data_string, format))
ValueError: time data '2020-05-16 21:26:55' does not match format '%Y-%m-%d %H:%M:%S.%f'
-----------------------------------------------------------------

-----------------------------------------------------------------
2020-05-17 00:00:00.396336
Restarting...
-----------------------------------------------------------------

